Workbook

Sheet 設定
A1: ■ 等級基準テーブル | K1: ■ 昇降給マトリクス
A2: 等級キー | B2: 等級 | C2: 区分 | D2: 月収下限 | E2: 月収上限 | F2: 半期基準粗利(1.0倍) | G2: 半期目標粗利(3.0倍) | H2: 等級グループ | K2: 粗利判定＼バリュー | L2: 要改善 | M2: 標準 | N2: 高い
A3: B1 | B3: B | C3: 1年目 | D3: 240000 | E3: 280000 | F3: 166667 | G3: 500000 | H3: B・A | K3: S | L3: A | M3: S | N3: S
A4: B2 | B4: B | C4: 2年目 | D4: 240000 | E4: 280000 | F4: 500000 | G4: 1500000 | H4: B・A | K4: A | L4: B | M4: A | N4: S
A5: B3 | B5: B | C5: 3年目〜 | D5: 240000 | E5: 280000 | F5: 833334 | G5: 2500000 | H5: B・A | K5: B | L5: C | M5: B | N5: A
A6: A1 | B6: A1 | D6: 300000 | E6: 349000 | F6: 1800000 | G6: 5400000 | H6: B・A | K6: C | L6: D | M6: C | N6: B
A7: A2 | B7: A2 | D7: 350000 | E7: 400000 | F7: 2100000 | G7: 6300000 | H7: B・A | K7: D | L7: E | M7: D | N7: D
A8: L1 | B8: L1 | D8: 450000 | E8: 499000 | F8: 2700000 | G8: 8100000 | H8: L・M | K8: E | L8: F | M8: E | N8: E
A9: L2 | B9: L2 | D9: 500000 | E9: 550000 | F9: 3000000 | G9: 9000000 | H9: L・M | K9: F | L9: F | M9: F | N9: F
A10: M1 | B10: M1 | D10: 600000 | E10: 649000 | F10: 3600000 | G10: 10800000 | H10: L・M
A11: M2 | B11: M2 | D11: 650000 | E11: 700000 | F11: 3900000 | G11: 11700000 | H11: L・M | K11: ■ 改定額（最終判定×等級グループ・円）
K12: 最終判定＼グループ | L12: B・A | M12: L・M
A13: ■ 粗利判定（倍率→判定）※LOOKUP用に昇順 | K13: S | L13: 12000 | M13: 18000
A14: 倍率下限 | B14: 判定 | C14: 状態 | K14: A | L14: 8000 | M14: 12000
A15: 0 | B15: F | C15: 大きく不足している | K15: B | L15: 4000 | M15: 6000
A16: 1 | B16: E | C16: 大きく改善が必要 | K16: C | L16: 0 | M16: 0
A17: 1.5 | B17: D | C17: 改善が必要 | K17: D | L17: -4000 | M17: -6000
A18: 2 | B18: C | C18: 据え置き水準 | K18: E | L18: -8000 | M18: -12000
A19: 2.5 | B19: B | C19: 目標には届かないが近い水準 | K19: F | L19: -12000 | M19: -18000
A20: 3 | B20: A | C20: 目標を達成している
A21: 3.5 | B21: S | C21: 目標を大きく超えている
A43: ■ 運用情報
A44: 対象期 | B44: 2026前期

Sheet 面談シート
A1: 個人面談シート | E1: 等級キー | F1: =IF($B$6="","",IF($B$6="B","B"&IF($D$6="",1,MIN($D$6,3)),$B$6))
A2: 対象期 | B2: =設定!$B$44 | E2: 等級グループ | F2: =IFERROR(VLOOKUP($F$1,設定!$A$3:$H$11,8,FALSE),"")
A3: 氏名
A4: 社員ID
A5: 区分
A6: 等級 | C6: B年次
A7: ユニット | C7: ユニット長
A8: 現在月給
A9: ■ 粗利評価
A10: 半期基準粗利 | B10: =IF($F$1="","",IFERROR(VLOOKUP($F$1,設定!$A$3:$H$11,6,FALSE),""))
A11: 実績半期粗利
A12: 粗利倍率 | B12: =IF(OR($B$10="",$B$11=""),"",$B$11/$B$10)
A13: 粗利判定 | B13: =IF($B$12="","",LOOKUP($B$12,設定!$A$15:$A$21,設定!$B$15:$B$21))
A15: ■ バリュー評価（各3点・9項目・27点満点）
A16: 項目 | B16: 自己 | C16: ユニット長
A17: 信頼
A18: 疑問
A19: 熱量
A20: 創造
A21: 実行速度
A22: 主体性
A23: チームワーク
A24: 挑戦
A25: 責任
A26: 合計 | B26: =IF(COUNT(B17:B25)=0,"",SUM(B17:B25)) | C26: =IF(COUNT(C17:C25)=0,"",SUM(C17:C25))
A27: 確定合計（既定＝ユニット長／会議で上書き可） | B27: =IF($B$4="","",IF(C26<>"",C26,B26))
A28: バリュー判定 | B28: =IF($B$27="","",IF($B$27>=23,"高い",IF($B$27>=17,"標準","要改善")))
A30: ■ スキル評価（1〜5・10項目）※昇給額には使わない
A31: 項目 | B31: 自己 | C31: ユニット長 | D31: 確定
A32: 全体管理 | D32: =IF($B$4="","",IF(C32<>"",C32,B32))
A33: 予算管理 | D33: =IF($B$4="","",IF(C33<>"",C33,B33))
A34: 企画 | D34: =IF($B$4="","",IF(C34<>"",C34,B34))
A35: PR・集客 | D35: =IF($B$4="","",IF(C35<>"",C35,B35))
A36: クリエイティブ | D36: =IF($B$4="","",IF(C36<>"",C36,B36))
A37: 事務局 | D37: =IF($B$4="","",IF(C37<>"",C37,B37))
A38: 運営制作 | D38: =IF($B$4="","",IF(C38<>"",C38,B38))
A39: 進行制作 | D39: =IF($B$4="","",IF(C39<>"",C39,B39))
A40: 運営現場 | D40: =IF($B$4="","",IF(C40<>"",C40,B40))
A41: 進行現場 | D41: =IF($B$4="","",IF(C41<>"",C41,B41))
A42: 全項目3以上 | B42: =IF(COUNT(D32:D41)<10,"",IF(MIN(D32:D41)>=3,"○","×"))
...
